Workbook
Name CÓDIGOS_TIPO_DE_FUENTES_DE_FINANCIACIÓN: '[1]Fuentes de Financiación'!$B$3:$B$218
Name Energia_Sostenible: PD_2024_2027!#REF!
Name Energia_Sostenible: Listas!#REF!
Name SALDO_PPT: [1]Presentación!$E$3
Name SALDO_TES: [1]Presentación!$G$3

Sheet Contratos Marco
D1: EMERGENCIAS
B2: Datos Generales Contratación | M2: Datos Financieros Gerencia y proyectos_ Si aplica
B3: # | C3: Contrato Marco | D3: Entidad Contratante [Ejemplo: ADI | Secretaría de Obras Públicas | Edubar | PDO] | E3: Convenio o Contrato Interadministrativo [Si no aplica: N/A] | F3: Aliado Contrato Interadministrativo [Si no aplica: N/A] | G3: Fuente de Recurso [ Propios_Alcaldía | Cofinanciación | Otros ] | I3: Fecha de Inicio [dd/mm/aaaa] | J3: Fecha de Terminación Inicial [dd/mm/aaaa] | K3: Fecha de Terminación Final [dd/mm/aaaa] | M3: Valor inicial Contrato de Gerencia | N3: Valor total adicionado Contrato de Gerencia | O3: Valor total Contrato de Gerencia | P3: Valor para Gerencia | Q3: Valor total Facturado Contrato de Gerencia | R3: Valor total Pagado Contrato de Gerencia | S3: Valor para Ejecución [Contrato Ejecución + Interventoría] | T3: Valor total Facturado Ejecución [Contrato Ejecución + Interventoría] | U3: Valor total Pagado Ejecución [Contrato Ejecución + Interventoría] | W3: Observaciones
B4: 1 | C4: ECOPARQUE UF1 Y TREN TAJAMAR | D4: Distrito Especial Industrial y Portuario de Barranquilla NIT. 890.102.018-1 | E4: Contrato Interadministrativo No. CD-12-2020-2435 | F4: N/A | G4: Cofinanciación | I4: 44327 | J4: 44561 | K4: 45382 | M4: =+P4+S4 -> 133184208608 | O4: =+M4+N4 -> 133184208608 | P4: 2420000000 | Q4: 2178000000 | R4: =Q4 -> 2178000000 | S4: 130764208608 | T4: 1.1137917e+11 | U4: 1.0877791e+11
B5: 2 | C5: ECOPARQUE UF2 | D5: 1. Empresa Nacional Promotora del Desarrollo Territorial – Enterritorio – Ministerio de Hacienda y Crédito Público NIT 899.999.316-1 en calidad de mandatario del Departamento Nacional de Planeación (DNP) en virtud del Contrato Interadministrativo de Mandato DNP 877-2021 Enterritorio 221009 – ENTERRITORIO. 2. Distrito Especial Industrial y Portuario de Barranquilla NIT. 890.102.018-1 3. Establecimiento Público Ambiental Barranquilla Verde NIT. 901.034.433-0 | E5: Contrato Específico No. 2210698 Derivado del Pacto Funcional Atlántico - CONTRATO DE MANDATO N.º 221009 – Suscrito entre EL DNP Y ENTERRITORIO | F5: ENTERRITORIO | G5: Distrito: $ 16.408.845.503,32 DNP: $105.000.000.000 | I5: 44544 | J5: 45121 | M5: =121408845503.32+508517168 -> 1.2191736e+11 | O5: =+M5 -> 1.2191736e+11 | P5: 5.7380996e+09 | Q5: 4.3035747e+09 | R5: 4.3035747e+09 | S5: =115670745934+508517168 -> 116179263102 | T5: 9.7371767e+10 | U5: 9.7371767e+10
B6: 3 | C6: RECUPERACIÓN PLAYA PUERTO MOCHO | D6: Distrito Especial Industrial y Portuario de Barranquilla NIT. 890.102.018-1 | E6: Contrato Interadministrativo No.CD-12-2021-4477 | F6: N/A | G6: Distrito | I6: 44531 | J6: 44926 | K6: 45337 | M6: 2.6776982e+10 | O6: =+M6+N6 -> 2.6776982e+10 | P6: 1.195401e+09 | Q6: 1.0692198e+09 | R6: =1069219751.2-112898979.92 -> 9.5632077e+08 | S6: =23091329705+1673561307 -> 24764891012 | T6: =13753311978.97+850671212 -> 1.4603983e+10 | U6: =+(13753311978.97-2014528783)+850671212 -> 1.2589454e+10 | W6: Se esra trámitando una prórroga al Contrato Interadministrativo por 2 meses más a partir de la fecha de terminación del mismo.
B7: 4 | C7: GRAN BAZAR Y NUEVOS MERCADOS | D7: Distrito Especial Industrial y Portuario de Barranquilla NIT. 890.102.018-1 | E7: Contrato Interadministrativo No. CD-57-2021-2989 | F7: Gobernación del Atlántico NIT: 890.102.006-1 | G7: Cofinanciación Gobernación del Atlántico por valor de $17.500.000.000 | I7: 44328 | J7: 44561 | K7: 45504 | M7: 6700000000 | N7: 1.1638559e+11 | O7: =+M7+N7 -> 1.2308559e+11 | P7: 9.9238789e+09 | Q7: 8.931491e+09 | R7: =+Q7 -> 8.931491e+09 | S7: 1.1316171e+11 | T7: 9.2628533e+10 | U7: 8.0310588e+10
B8: 5 | C8: TEU - TRANSFORMACIÓN DE ENTORNOS URBANOS | D8: Distrito Especial Industrial y Portuario de Barranquilla NIT. 890.102.018-1 | E8: Contrato Interadministrativo No. CD-57-2020-2438 | F8: N/A | I8: 44706 | J8: 44926 | K8: 45504 | M8: 30000000000 | O8: 30000000000 | P8: 1926605505 | Q8: 1.6439367e+09 | R8: 1.6439367e+09 | S8: 28068651772 | T8: 24449905435 | U8: 24449905435
B9: 6 | C9: CAÑO DE LA AHUYAMA | D9: 1. Empresa Nacional Promotora del Desarrollo Territorial – Enterritorio – Ministerio de Hacienda y Crédito Público NIT 899.999.316-1 en calidad de mandatario del Departamento Nacional de Planeación (DNP) en virtud del Contrato Interadministrativo de Mandato DNP 877-2021 Enterritorio 221009 – ENTERRITORIO. 2. Distrito Especial Industrial y Portuario de Barranquilla NIT. 890.102.018-1 3. Establecimiento Público Ambiental Barranquilla Verde NIT. 901.034.433-0 | E9: Contrato Específico No. 2210681 Derivado del Pacto Funcional Atlántico - CONTRATO DE MANDATO N.º 221009 – Suscrito entre EL DNP Y ENTERRITORIO | F9: ENTERRITORIO | G9: Distrito: $ 4.747.433.502,01 DNP: $ 99.979.996.094 | I9: 44529 | J9: 45045 | K9: 45504 | M9: =+S9+O9 -> 1.0472743e+11 | O9: 4.7474335e+09 | P9: 4.7474335e+09 | Q9: 3.5605751e+09 | R9: 3.5605751e+09 | S9: =93425142894+6554853200 -> 99979996094 | T9: 5.5051036e+10 | U9: 5.4560733e+10
B10: 7 | C10: CICLOMONTAÑISMO | D10: Distrito Especial Industrial y Portuario de Barranquilla NIT. 890.102.018-1 | E10: CD-58-2021-4425 | F10: N/A | G10: Cofinanciación | I10: 44525 | J10: 44926 | K10: 45412 | M10: 3.3759879e+10 | O10: =+M10+N10 -> 3.3759879e+10 | P10: 1607613301 | Q10: 1.446852e+09 | R10: 1.446852e+09 | S10: 3.1980741e+10 | T10: 2.8779232e+10 | U10: 2.8779232e+10
B11: 8 | C11: HOSPITALES | D11: Distrito Especial Industrial y Portuario de Barranquilla NIT. 890.102.018-1 | E11: No. 012016001893 | F11: N/A | G11: Estampilla Prohospital ICLD FONPET | I11: 42524 | J11: 45657 | K11: 45657 | M11: 164361579387 | N11: =900213284+6000000000+2494297665+19170000000+28750000000 -> 57314510949 | O11: =+M11+N11 -> 221676090336 | P11: 0 | Q11: 0 | R11: 0 | S11: =+O11 -> 221676090336 | T11: =149768557393.23+13623178167.94 -> 1.6339174e+11 | U11: =149768557393.23+13055502565.61 -> 1.6282406e+11
B12: 9 | C12: BARRIOS A LA OBRA | D12: Distrito Especial Industrial y Portuario de Barranquilla NIT. 890.102.018-1 | E12: Contrato Interadministrativo No. CD-12-2020-2429 | F12: N/A | G12: Propios_Alcaldía | I12: 44442 | J12: 44561 | K12: 45656 | M12: 110625302170 | N12: 71726921600 | O12: =+M12+N12 -> 182352223770 | P12: 7883906190 | Q12: 5.4182428e+09 | R12: 5333717843 | S12: 173745194193 | T12: 1.2351558e+11 | U12: 1.2259868e+11 | W12: Se realizaron prorrogas y adiciones a contratos de obra e interventoria para ejecucion hasta 30 de julio del 2024 y con fecha de ejecucion de la gerencia hasta 30 de diciembre del 2024
B13: 10 | C13: AMPLIACIÓN Y MEJORAMIENTO DE IEDs | D13: Distrito Especial Industrial y Portuario de Barranquilla NIT. 890.102.018-1 | E13: Contrato Interadministrativo No. CD-05-2022-3691 | F13: N/A | G13: Cofinanciación | I13: 44757 | J13: 44926 | K13: 45382 | M13: 30000000000 | O13: =+M13+N13 -> 30000000000 | P13: 2392620000 | Q13: 2033727000 | R13: =+Q13 -> 2033727000 | S13: =25672996396.61+1349952660 -> 2.7022949e+10 | T13: =17405858399.13+874384041.14 -> 1.8280242e+10 | U13: =1934476065.17+4224296240.76+2964678266.08+2350000000+323844203 -> 1.1797295e+10 | W13: Se adeuda la suma de $6.482.947.665,26
B14: 11 | C14: MANTENIMIENTO DE LOS ESCENARIOS DEPORTIVOS DEL DISTRITO DE BARRANQUILLA | D14: Distrito Especial Industrial y Portuario de Barranquilla NIT. 890.102.018-1 | E14: Contrato Interadministrativo No. CD-58-2023-3275 | F14: N/A | G14: Cofinanciación | I14: 45070 | J14: 45291 | K14: 45503 | M14: 10000000000 | O14: =+M14+N14 -> 10000000000 | P14: 800000000 | Q14: 720000000 | R14: =+Q14 -> 720000000 | S14: 9200000000 | T14: 1.5960513e+09 | U14: 0 | W14: Se adeuda la suma de $ 1.596.051.256,56

Sheet Proyectos Base digitable
A1: ID | B1: Reporte a cargo de: | C1: Convenio o Contrato Interadministrativo | D1: Línea Estratégica Plan de Desarrollo 2024-2027 | E1: Sectores | F1: Programas | G1: Nombre Proyecto | H1: Localidad | I1: Barrios | J1: Dirección | K1: Localización | L1: x | M1: y | N1: Estado Proyecto | O1: Subestado Proyecto | P1: Valor total de proyecto | Q1: % Programado físico | R1: % Ejecutado físico | S1: Atraso | T1: Semáforo Cronograma | U1: Fecha de Adjudicación | V1: Fecha de Firma Contrato | W1: Fecha de Inicio | X1: Fecha de Terminación Inicial | Y1: Fecha de Terminación Final | Z1: Semáforo Fecha Terminación | AA1: Semáforo Críticos | AB1: ¿Proyecto con ampliación de plazo contractual? | AC1: Fecha estimada para terminación según prórroga a tramitar | AD1: Fecha de Entrega | AE1: No. Contrato Ejecución | AF1: Nombre Contratista Ejecución | AG1: Miembros Consorcios o UT | AH1: Representante Legal | AI1: No. Contrato Interventoría | AJ1: Nombre Contratista Interventoría | AK1: Miembros Consorcios o UT 2 | AL1: Representante Legal3 | AM1: Valor inicial de Obra | AN1: Valor total adicionado de obra | AO1: Valor total de Obra | AP1: Valor total Facturadode Obra | AQ1: Valor total Pagado de Obra | AR1: Valor inicial de Interventoría | AS1: Valor total adicionado de Interventoría | AT1: Valor total de Interventoría | AU1: Valor total Facturado de Interventoría | AV1: Valor total Pagado de Interventoría | AW1: Población Beneficiada [ Indicar cantidad y tipo de población. Ej: 100 Estudiantes ] | AX1: Indicador 1 | AY1: Indicador 2 | AZ1: Indicador 3 | BA1: Actividades Ejecutadas ultima semana | BB1: Observaciones de acciones ejecutivas | BC1: Emblemático Gerente
A2: 1 | B2: Obras Públicas | C2: CD-12-2020-2429 | D2: Línea Económica_Ciudad Dinámica | E2: Trasporte | F2: Barrios a la obra | G2: BAO_VII_2429_M1 | H2: Varias | I2: La Paz - El Carmen - Olaya - Santuario - Evaristo Sourdis - Villa San Pedro II - Villa Flor - Campo Alegre - Sevilla Real - Las Granjas - Villa Sevilla - Corregimiento La Playa - Alameda Del Rio - El Pueblo - Los Angeles III - Siete de Abril - Boyacá | J2: - | K2: 10°58'6.7'' N 74°46'52.8'' O | L2: -74.781333 | M2: 10.968528 | N2: Postcontractual | O2: Terminado | P2: =+AO2+AT2 -> 1.7501823e+10 | Q2: 1 | R2: 1 | S2: =+R2-Q2 -> 0 | T2: {=+_xlfn.IFS($P2<=10000000000,IF(S2>-0.05,"Verde",IF(S2<=-0.1,"Rojo","Amarillo")),$P2>10000000000,IF(S2>-0.03,"Verde",IF(S2<=-0.07,"Rojo","Amarillo")))} -> Verde | U2: 44305 | V2: 44334 | W2: 44442 | X2: 44561 | Y2: 45504 | Z2: =+IF(AND(O2="En_Ejecución",OR(T2="Rojo",T2="Amarillo")),IF(($Y2-(TODAY())<15),"Rojo",IF(($Y2-TODAY())>=45,"Verde","Amarillo")),O2) -> Terminado | AA2: =+IF(AND(Z2="Amarillo",T2="Rojo"),"En_Seguimiento",IF(AND(Z2="Rojo",T2="Amarillo"),"En_Seguimiento",IF(AND(Z2="Rojo",T2="Rojo"),"En_Seguimiento",IF(AND(Z2="Suspendido",T2="Amarillo"),"En_Seguimiento",IF(AND(Z2="Suspendido",T2="Rojo"),"En_Seguimiento","-"))))) -> - | AB2: No | AD2: 45504 | AE2: EDU-356-2021 | AF2: CONSORCIO VIAL DISTRITAL | AG2: HB INGENIEROS CIVILES S.A.S. (80%) A.S.B. LIMITADA (10%) CONSTRUCCIONES CARCIV S.A.S. (10%) | AH2: Alvaro Henriquez Medrano | AI2: EDU-388-2021 | AJ2: CONSORCIO INTERVIAS BARRANQUILLA | AK2: COMPAÑÍA DE INTERVENTORIAS Y CONSULTORIAS DE LA COSTA S.A.S. (59%) ROCCIA S.A.S. (30%) CGB (10%) INEXIA S.A.S. (1%) | AL2: CARLOS MASS GUERRERO | AM2: 10087941782 | AN2: 6614286460 | AO2: =AM2+AN2 -> 16702228242 | AP2: 15865781158 | AQ2: 15865781158 | AR2: 2589999997 | AS2: 1425826605 | AT2: 7.9959426e+08 | AU2: 3.4917114e+09 | AV2: 3.1115436e+09 | AW2: 4880 Habitantes | AX2: Metros Lineales intervenidos | AY2: Kilometros recuperados por Barrio | AZ2: Tramos viales inaugurados | BA2: Proceso de liquidación | BC2: No
A3: =+A2+1 -> 2 | B3: Obras Públicas | C3: CD-12-2020-2429 | D3: Línea Económica_Ciudad Dinámica | E3: Trasporte | F3: Barrios a la obra | G3: BAO_VII_2429_M2 | H3: Varias | I3: La Gloria - El Bosque - El Pueblo - California - Cordialidad - Villa San Pedro I - Villa San Carlos - Santo Domingo de Guzman | J3: - | K3: 10°58'6.7'' N 74°46'52.8'' O | N3: Postcontractual | O3: Terminado | P3: =+AO3+AT3 -> 1.8006561e+10 | Q3: 1 | R3: 1 | S3: =+R3-Q3 -> 0 | T3: {=+_xlfn.IFS($P3<=10000000000,IF(S3>-0.05,"Verde",IF(S3<=-0.1,"Rojo","Amarillo")),$P3>10000000000,IF(S3>-0.03,"Verde",IF(S3<=-0.07,"Rojo","Amarillo")))} -> Verde | U3: 44305 | V3: 44334 | W3: 44442 | X3: 44561 | Y3: 44985 | Z3: =+IF(AND(O3="En_Ejecución",OR(T3="Rojo",T3="Amarillo")),IF(($Y3-(TODAY())<15),"Rojo",IF(($Y3-TODAY())>=45,"Verde","Amarillo")),O3) -> Terminado | AA3: =+IF(AND(Z3="Amarillo",T3="Rojo"),"En_Seguimiento",IF(AND(Z3="Rojo",T3="Amarillo"),"En_Seguimiento",IF(AND(Z3="Rojo",T3="Rojo"),"En_Seguimiento",IF(AND(Z3="Suspendido",T3="Amarillo"),"En_Seguimiento",IF(AND(Z3="Suspendido",T3="Rojo"),"En_Seguimiento","-"))))) -> - | AB3: No | AD3: 44985 | AE3: EDU-357-2021 | AF3: BF CONSTRUYE SAS | AG3: BF CONSTRUYE S.A.S. (100%) | AH3: Maria Isabel Valenzuela Benitez | AI3: EDU-389-2021 | AJ3: CONSORCIO RUT 2021 | AK3: COINCO DE COLOMBIA S.A.S. (50%) INGENIERIA MASTER S.A.S. (25%) CONSULTORIA TECNICA DE OBRAS S.A.S. (25%) | AL3: DAVINSON GRAVINI POLO | AM3: 7596189806 | AN3: 9.5106915e+09 | AO3: =AM3+AN3 -> 1.7106881e+10 | AP3: 17105644167 | AQ3: 17105644167 | AR3: 2353659350 | AS3: 1.9320403e+09 | AT3: 8.9967999e+08 | AU3: 3242593169 | AV3: 3242593169 | AW3: 3204 Habitantes | AX3: Metros Lineales intervenidos | AY3: Kilometros recuperados por Barrio | AZ3: Tramos viales inaugurados | BA3: Proceso de liquidación | BC3: No
A4: =+A3+1 -> 3 | B4: Obras Públicas | C4: CD-12-2020-2429 | D4: Línea Económica_Ciudad Dinámica | E4: Trasporte | F4: Barrios a la obra | G4: BAO_VII_2429_M3 | H4: Suroccidente | I4: Por Fin - La Manga | J4: - | K4: 10°58'6.7'' N 74°46'52.8'' O | N4: Postcontractual | O4: Terminado | P4: =+AO4+AT4 -> 1.3596535e+10 | Q4: 1 | R4: 1 | S4: =+R4-Q4 -> 0 | T4: {=+_xlfn.IFS($P4<=10000000000,IF(S4>-0.05,"Verde",IF(S4<=-0.1,"Rojo","Amarillo")),$P4>10000000000,IF(S4>-0.03,"Verde",IF(S4<=-0.07,"Rojo","Amarillo")))} -> Verde | U4: 44305 | V4: 44334 | W4: 44442 | X4: 44561 | Y4: 45626 | Z4: =+IF(AND(O4="En_Ejecución",OR(T4="Rojo",T4="Amarillo")),IF(($Y4-(TODAY())<15),"Rojo",IF(($Y4-TODAY())>=45,"Verde","Amarillo")),O4) -> Terminado | AA4: =+IF(AND(Z4="Amarillo",T4="Rojo"),"En_Seguimiento",IF(AND(Z4="Rojo",T4="Amarillo"),"En_Seguimiento",IF(AND(Z4="Rojo",T4="Rojo"),"En_Seguimiento",IF(AND(Z4="Suspendido",T4="Amarillo"),"En_Seguimiento",IF(AND(Z4="Suspendido",T4="Rojo"),"En_Seguimiento","-"))))) -> - | AB4: No | AD4: 45626 | AE4: EDU-358-2021 | AF4: CONSTRUCTORA DE OBRAS DE VIVIENDA E INGENIERIA SAS (COVEIN) | AG4: CONSTRUCTORA DE OBRAS DE VIVIENDA E INGENIERIA S.A.S. (COVEIN) (100%) | AH4: Guillermo Alberto Cuello Gieseken | AI4: EDU-389-2021 | AJ4: CONSORCIO RUT 2021 | AK4: COINCO DE COLOMBIA S.A.S. (50%) INGENIERIA MASTER S.A.S. (25%) CONSULTORIA TECNICA DE OBRAS S.A.S. (25%) | AL4: DAVINSON GRAVINI POLO | AM4: 7615449800 | AN4: 5301748132 | AO4: =AM4+AN4 -> 12917197932 | AP4: 8.7661794e+09 | AQ4: 8.7661794e+09 | AR4: 0 | AS4: 0 | AT4: 6.7933741e+08 | AU4: 0 | AV4: 0 | AW4: 588 Habitantes | AX4: Metros Lineales intervenidos | AY4: Kilometros recuperados por Barrio | AZ4: Tramos viales inaugurados | BA4: Se realizo actividades de Nivelación y replanteo de via, Excavación y retiro de material, Señalizacion de frentes de obra, instalación de relleno en material seleccionado, instalación de concreto fluido, fundida en pavimento en concreto rigido | BC4: No
A5: =+A4+1 -> 4 | B5: Obras Públicas | C5: CD-12-2020-2429 | D5: Línea Económica_Ciudad Dinámica | E5: Trasporte | F5: Barrios a la obra | G5: BAO_VII_2429_M4 | H5: Metropolitana | I5: Siete de Abril | J5: - | K5: 10°58'6.7'' N 74°46'52.8'' O | N5: Postcontractual | O5: Terminado | P5: =+AO5+AT5 -> 1.370699e+10 | Q5: 1 | R5: 1 | S5: =+R5-Q5 -> 0 | T5: {=+_xlfn.IFS($P5<=10000000000,IF(S5>-0.05,"Verde",IF(S5<=-0.1,"Rojo","Amarillo")),$P5>10000000000,IF(S5>-0.03,"Verde",IF(S5<=-0.07,"Rojo","Amarillo")))} -> Verde | U5: 44305 | V5: 44334 | W5: 44442 | X5: 44561 | Y5: 45504 | Z5: =+IF(AND(O5="En_Ejecución",OR(T5="Rojo",T5="Amarillo")),IF(($Y5-(TODAY())<15),"Rojo",IF(($Y5-TODAY())>=45,"Verde","Amarillo")),O5) -> Terminado | AA5: =+IF(AND(Z5="Amarillo",T5="Rojo"),"En_Seguimiento",IF(AND(Z5="Rojo",T5="Amarillo"),"En_Seguimiento",IF(AND(Z5="Rojo",T5="Rojo"),"En_Seguimiento",IF(AND(Z5="Suspendido",T5="Amarillo"),"En_Seguimiento",IF(AND(Z5="Suspendido",T5="Rojo"),"En_Seguimiento","-"))))) -> - | AB5: No | AD5: 45504 | AE5: EDU-359-2021 | AF5: CONSORCIO BARRIOS A LA OBRA 2021 | AG5: EDUARDO ENRIQUE CABALLERO AVILA (50%) CONSTRUCCIONES E INVERSIONES FVR S.A.S. (40%) PROYECTOS DE INGENIERÍA INOSVA S.A.S. (10%) | AH5: Eduardo Enrique Caballero Avila | AI5: EDU-389-2021 | AJ5: CONSORCIO RUT 2021 | AK5: COINCO DE COLOMBIA S.A.S. (50%) INGENIERIA MASTER S.A.S. (25%) CONSULTORIA TECNICA DE OBRAS S.A.S. (25%) | AL5: DAVINSON GRAVINI POLO | AM5: 7591113018 | AN5: 5431020644 | AO5: =AM5+AN5 -> 13022133662 | AP5: 1.2360972e+10 | AQ5: 1.2360972e+10 | AR5: 0 | AS5: 0 | AT5: 6.8485616e+08 | AU5: 0 | AV5: 0 | AW5: 2392 Habitantes | AX5: Metros Lineales intervenidos | AY5: Kilometros recuperados por Barrio | AZ5: Tramos viales inaugurados | BA5: Tramites de recibo final y terminacion, cierres de actas de vecindad, pqrs y pendientes en campo | BC5: No
A6: =+A5+1 -> 5 | B6: Obras Públicas | C6: CD-12-2020-2429 | D6: Línea Económica_Ciudad Dinámica | E6: Trasporte | F6: Barrios a la obra | G6: BAO_VII_2429_M5 | H6: Varias | I6: Colombia - El Porvenir - Altos del Limon - Centro - Villa Santos - Las Americas - Las Malvinas - Barrios Abajo - La Chinita - Las Flores - San Salvador - San Francisco - La Luz - Chiquinquira - Las Mercedes - Los Jobos - San Jose - La Victoria - Las Delicias - La Ceiba - San Felipe - Olaya Herrera - Las Estrellas - La Florida - Santa Maria - San Luis - Los Andes | J6: - | K6: 10°58'6.7'' N 74°46'52.8'' O | N6: Postcontractual | O6: Terminado | P6: =+AO6+AT6 -> 1.6211544e+10 | Q6: 1 | R6: 1 | S6: =+R6-Q6 -> 0 | T6: {=+_xlfn.IFS($P6<=10000000000,IF(S6>-0.05,"Verde",IF(S6<=-0.1,"Rojo","Amarillo")),$P6>10000000000,IF(S6>-0.03,"Verde",IF(S6<=-0.07,"Rojo","Amarillo")))} -> Verde | U6: 44305 | V6: 44334 | W6: 44442 | X6: 44561 | Y6: 45565 | Z6: =+IF(AND(O6="En_Ejecución",OR(T6="Rojo",T6="Amarillo")),IF(($Y6-(TODAY())<15),"Rojo",IF(($Y6-TODAY())>=45,"Verde","Amarillo")),O6) -> Terminado | AA6: =+IF(AND(Z6="Amarillo",T6="Rojo"),"En_Seguimiento",IF(AND(Z6="Rojo",T6="Amarillo"),"En_Seguimiento",IF(AND(Z6="Rojo",T6="Rojo"),"En_Seguimiento",IF(AND(Z6="Suspendido",T6="Amarillo"),"En_Seguimiento",IF(AND(Z6="Suspendido",T6="Rojo"),"En_Seguimiento","-"))))) -> - | AB6: No | AD6: 45565 | AE6: EDU-360-2021 | AF6: A CONSTRUIR SA | AG6: A CONSTRUIR S.A. (100%) | AH6: Ivan Alberto Jimenez Aguirre | AI6: EDU-388-2021 | AJ6: CONSORCIO INTERVIAS BARRANQUILLA | AK6: COMPAÑÍA DE INTERVENTORIAS Y CONSULTORIAS DE LA COSTA S.A.S. (59%) ROCCIA S.A.S. (30%) CGB (10%) INEXIA S.A.S. (1%) | AL6: CARLOS MASS GUERRERO | AM6: 9610407989 | AN6: 5860489797 | AO6: =AM6+AN6 -> 15470897786 | AP6: 14553426871 | AQ6: 14553426871 | AR6: 0 | AS6: 0 | AT6: 7.4064615e+08 | AU6: 0 | AV6: 0 | AW6: 3100 Habitantes | AX6: Metros Lineales intervenidos | AY6: Kilometros recuperados por Barrio | AZ6: Tramos viales inaugurados | BA6: Tramites de recibo final y terminacion, cierres de actas de vecindad, pqrs y pendientes en campo | BC6: No
A7: =+A6+1 -> 6 | B7: Obras Públicas | C7: CD-12-2020-2429 | D7: Línea Económica_Ciudad Dinámica | E7: Trasporte | F7: Barrios a la obra | G7: BAO_VII_2429_M6 | H7: Varias | I7: Las Americas - Santuario - Las Malvinas - Ciudadela 20 de Julio - Ciudad Modesto | J7: - | K7: 10°58'6.7'' N 74°46'52.8'' O | N7: Postcontractual | O7: Terminado | P7: =+AO7+AT7 -> 1.5213349e+10 | Q7: 1 | R7: 1 | S7: =+R7-Q7 -> 0 | T7: {=+_xlfn.IFS($P7<=10000000000,IF(S7>-0.05,"Verde",IF(S7<=-0.1,"Rojo","Amarillo")),$P7>10000000000,IF(S7>-0.03,"Verde",IF(S7<=-0.07,"Rojo","Amarillo")))} -> Verde | U7: 44305 | V7: 44334 | W7: 44442 | X7: 44561 | Y7: 45565 | Z7: =+IF(AND(O7="En_Ejecución",OR(T7="Rojo",T7="Amarillo")),IF(($Y7-(TODAY())<15),"Rojo",IF(($Y7-TODAY())>=45,"Verde","Amarillo")),O7) -> Terminado | AA7: =+IF(AND(Z7="Amarillo",T7="Rojo"),"En_Seguimiento",IF(AND(Z7="Rojo",T7="Amarillo"),"En_Seguimiento",IF(AND(Z7="Rojo",T7="Rojo"),"En_Seguimiento",IF(AND(Z7="Suspendido",T7="Amarillo"),"En_Seguimiento",IF(AND(Z7="Suspendido",T7="Rojo"),"En_Seguimiento","-"))))) -> - | AB7: No | AD7: 45565 | AE7: EDU-361-2021 | AF7: DONADO ARCE & CIA SAS | AG7: DONADO ARCE & CIA S.A.S. (100%) | AH7: Roberto Carlo Donado Arce | AI7: EDU-388-2021 | AJ7: CONSORCIO INTERVIAS BARRANQUILLA | AK7: COMPAÑÍA DE INTERVENTORIAS Y CONSULTORIAS DE LA COSTA S.A.S. (59%) ROCCIA S.A.S. (30%) CGB (10%) INEXIA S.A.S. (1%) | AL7: CARLOS MASS GUERRERO | AM7: 8708323997 | AN7: 5809982432 | AO7: =AM7+AN7 -> 14518306429 | AP7: 1.2927145e+10 | AQ7: 1.2927145e+10 | AR7: 0 | AS7: 0 | AT7: 6.9504226e+08 | AU7: 0 | AV7: 0 | AW7: 2916 Habitantes | AX7: Metros Lineales intervenidos | AY7: Kilometros recuperados por Barrio | AZ7: Tramos viales inaugurados | BA7: Tramites de recibo final y terminacion, cierres de actas de vecindad, pqrs y pendientes en campo | BC7: No
A8: =+A7+1 -> 7 | B8: Obras Públicas | C8: CD-12-2020-2429 | D8: Línea Económica_Ciudad Dinámica | E8: Trasporte | F8: Barrios a la obra | G8: BAO_VII_2429_M7 | H8: Varias | I8: El Bosque - El Eden 2000 - Florida Sur - Evaristo Sourdis - Villa del Rosario - Ciudad Jardin - Las Estrellas | J8: - | K8: 10°58'6.7'' N 74°46'52.8'' O | N8: Postcontractual | O8: Terminado | P8: =+AO8+AT8 -> 1.6944274e+10 | Q8: 1 | R8: 1 | S8: =+R8-Q8 -> 0 | T8: {=+_xlfn.IFS($P8<=10000000000,IF(S8>-0.05,"Verde",IF(S8<=-0.1,"Rojo","Amarillo")),$P8>10000000000,IF(S8>-0.03,"Verde",IF(S8<=-0.07,"Rojo","Amarillo")))} -> Verde | U8: 44305 | V8: 44334 | W8: 44442 | X8: 44561 | Y8: 45428 | Z8: =+IF(AND(O8="En_Ejecución",OR(T8="Rojo",T8="Amarillo")),IF(($Y8-(TODAY())<15),"Rojo",IF(($Y8-TODAY())>=45,"Verde","Amarillo")),O8) -> Terminado | AA8: =+IF(AND(Z8="Amarillo",T8="Rojo"),"En_Seguimiento",IF(AND(Z8="Rojo",T8="Amarillo"),"En_Seguimiento",IF(AND(Z8="Rojo",T8="Rojo"),"En_Seguimiento",IF(AND(Z8="Suspendido",T8="Amarillo"),"En_Seguimiento",IF(AND(Z8="Suspendido",T8="Rojo"),"En_Seguimiento","-"))))) -> - | AB8: No | AD8: 45428 | AE8: EDU-362-2021 | AF8: CONSTRUCTORA FG SA | AG8: CONSTRUCTORA FG S.A. (100%) | AH8: Eduardo Santos Martinez | AI8: EDU-388-2021 | AJ8: CONSORCIO INTERVIAS BARRANQUILLA | AK8: COMPAÑÍA DE INTERVENTORIAS Y CONSULTORIAS DE LA COSTA S.A.S. (59%) ROCCIA S.A.S. (30%) CGB (10%) INEXIA S.A.S. (1%) | AL8: CARLOS MASS GUERRERO | AM8: 10200564715 | AN8: 5969587668 | AO8: =AM8+AN8 -> 16170152383 | AP8: 15284701905 | AQ8: 15284701905 | AR8: 0 | AS8: 0 | AT8: 7.7412192e+08 | AU8: 0 | AV8: 0 | AW8: 2248 Habitantes | AX8: Metros Lineales intervenidos | AY8: Kilometros recuperados por Barrio | AZ8: Tramos viales inaugurados | BA8: Proceso de liquidación | BC8: No
A9: =+A8+1 -> 8 | B9: Obras Públicas | C9: CD-12-2020-2429 | D9: Línea Económica_Ciudad Dinámica | E9: Trasporte | F9: Barrios a la obra | G9: BAO_VII_2429_M8 | H9: Suroccidente | I9: Me Quejo - San Felipe - Carlos Meisel - La Esmeralda - La Libertad | J9: - | K9: 10°58'6.7'' N 74°46'52.8'' O | N9: Postcontractual | O9: Terminado | P9: =+AO9+AT9 -> 1.3792195e+10 | Q9: 1 | R9: 1 | S9: =+R9-Q9 -> 0 | T9: {=+_xlfn.IFS($P9<=10000000000,IF(S9>-0.05,"Verde",IF(S9<=-0.1,"Rojo","Amarillo")),$P9>10000000000,IF(S9>-0.03,"Verde",IF(S9<=-0.07,"Rojo","Amarillo")))} -> Verde | U9: 44305 | V9: 44334 | W9: 44442 | X9: 44561 | Y9: 45504 | Z9: =+IF(AND(O9="En_Ejecución",OR(T9="Rojo",T9="Amarillo")),IF(($Y9-(TODAY())<15),"Rojo",IF(($Y9-TODAY())>=45,"Verde","Amarillo")),O9) -> Terminado | AA9: =+IF(AND(Z9="Amarillo",T9="Rojo"),"En_Seguimiento",IF(AND(Z9="Rojo",T9="Amarillo"),"En_Seguimiento",IF(AND(Z9="Rojo",T9="Rojo"),"En_Seguimiento",IF(AND(Z9="Suspendido",T9="Amarillo"),"En_Seguimiento",IF(AND(Z9="Suspendido",T9="Rojo"),"En_Seguimiento","-"))))) -> - | AB9: No | AD9: 45504 | AE9: EDU-363-2021 | AF9: CONSORCIO VIAS URBANAS BARRANQUILLA 2021 | AG9: SOLUCIONES DE INFRAESTRUCTURA Y LOGISTICA S.A.S. (60%) TOSHIRA KENETSU S.A.S. (15%) INFRAESTRUCTURA TÉCNICA COLOMBIANA S.A.S. (25%) | AH9: Fabiam Alvarado Paternina | AI9: EDU-389-2021 | AJ9: CONSORCIO RUT 2021 | AK9: COINCO DE COLOMBIA S.A.S. (50%) INGENIERIA MASTER S.A.S. (25%) CONSULTORIA TECNICA DE OBRAS S.A.S. (25%) | AL9: DAVINSON GRAVINI POLO | AM9: 7638300700 | AN9: 5464780815 | AO9: =AM9+AN9 -> 13103081515 | AP9: 12447568529 | AQ9: 12447568529 | AR9: 0 | AS9: 0 | AT9: 6.8911335e+08 | AU9: 0 | AV9: 0 | AW9: 2048 Habitantes | AX9: Metros Lineales intervenidos | AY9: Kilometros recuperados por Barrio | AZ9: Tramos viales inaugurados | BA9: Proceso de liquidación | BC9: No
A10: =+A9+1 -> 9 | B10: Obras Públicas | C10: CD-12-2020-2429 | D10: Línea Económica_Ciudad Dinámica | E10: Trasporte | F10: Barrios a la obra | G10: BAO_VII_2429_M9 | H10: Varias | I10: Barlovento - Kalamary - San Roque | J10: - | K10: 10°58'6.7'' N 74°46'52.8'' O | N10: Postcontractual | O10: Terminado | P10: =+AO10+AT10 -> 1.3025165e+10 | Q10: 1 | R10: 1 | S10: =+R10-Q10 -> 0 | T10: {=+_xlfn.IFS($P10<=10000000000,IF(S10>-0.05,"Verde",IF(S10<=-0.1,"Rojo","Amarillo")),$P10>10000000000,IF(S10>-0.03,"Verde",IF(S10<=-0.07,"Rojo","Amarillo")))} -> Verde | U10: 44305 | V10: 44334 | W10: 44442 | X10: 44561 | Y10: 45596 | Z10: =+IF(AND(O10="En_Ejecución",OR(T10="Rojo",T10="Amarillo")),IF(($Y10-(TODAY())<15),"Rojo",IF(($Y10-TODAY())>=45,"Verde","Amarillo")),O10) -> Terminado | AA10: =+IF(AND(Z10="Amarillo",T10="Rojo"),"En_Seguimiento",IF(AND(Z10="Rojo",T10="Amarillo"),"En_Seguimiento",IF(AND(Z10="Rojo",T10="Rojo"),"En_Seguimiento",IF(AND(Z10="Suspendido",T10="Amarillo"),"En_Seguimiento",IF(AND(Z10="Suspendido",T10="Rojo"),"En_Seguimiento","-"))))) -> - | AB10: No | AD10: 45596 | AE10: EDU-364-2021 | AF10: CONSORCIO MODULO IX | AG10: CARLOS JOAQUIN PUCHE LIZARAZO (80%) DBD INGENIERIA S.A.S. (20%) | AH10: Carlos Joaquin Puche Lizarazo | AI10: EDU-389-2021 | AJ10: CONSORCIO RUT 2021 | AK10: COINCO DE COLOMBIA S.A.S. (50%) INGENIERIA MASTER S.A.S. (25%) CONSULTORIA TECNICA DE OBRAS S.A.S. (25%) | AL10: DAVINSON GRAVINI POLO | AM10: 7593881776 | AN10: 4780494120 | AO10: =AM10+AN10 -> 12374375896 | AP10: 10705414795 | AQ10: 10705414795 | AR10: 0 | AS10: 0 | AT10: 6.5078948e+08 | AU10: 0 | AV10: 0 | AW10: 440 Habitantes | AX10: Metros Lineales intervenidos | AY10: Kilometros recuperados por Barrio | AZ10: Tramos viales inaugurados | BA10: Tramites de recibo final y terminacion, cierres de actas de vecindad, pqrs y pendientes en campo | BC10: No
A11: =+A10+1 -> 10 | B11: Obras Públicas | C11: CD-12-2020-2429 | D11: Línea Económica_Ciudad Dinámica | E11: Trasporte | F11: Barrios a la obra | G11: BAO_VII_2429_M10 | H11: Varias | I11: Los Angeles - Los Angeles II - Los Angeles III - Las Nieves - Simon Bolivar | J11: - | K11: 10°58'6.7'' N 74°46'52.8'' O | N11: Postcontractual | O11: Terminado | P11: =+AO11+AT11 -> 1.3721468e+10 | Q11: 1 | R11: 1 | S11: =+R11-Q11 -> 0 | T11: {=+_xlfn.IFS($P11<=10000000000,IF(S11>-0.05,"Verde",IF(S11<=-0.1,"Rojo","Amarillo")),$P11>10000000000,IF(S11>-0.03,"Verde",IF(S11<=-0.07,"Rojo","Amarillo")))} -> Verde | U11: 44305 | V11: 44334 | W11: 44442 | X11: 44561 | Y11: 45596 | Z11: =+IF(AND(O11="En_Ejecución",OR(T11="Rojo",T11="Amarillo")),IF(($Y11-(TODAY())<15),"Rojo",IF(($Y11-TODAY())>=45,"Verde","Amarillo")),O11) -> Terminado | AA11: =+IF(AND(Z11="Amarillo",T11="Rojo"),"En_Seguimiento",IF(AND(Z11="Rojo",T11="Amarillo"),"En_Seguimiento",IF(AND(Z11="Rojo",T11="Rojo"),"En_Seguimiento",IF(AND(Z11="Suspendido",T11="Amarillo"),"En_Seguimiento",IF(AND(Z11="Suspendido",T11="Rojo"),"En_Seguimiento","-"))))) -> - | AB11: No | AD11: 45596 | AE11: EDU-365-2021 | AF11: CARLOS JOAQUIN PUCHE LIZARAZO | AG11: CARLOS JOAQUIN PUCHE LIZARAZO (100%) | AH11: Carlos Joaquin Puche Lizarazo | AI11: EDU-389-2021 | AJ11: CONSORCIO RUT 2021 | AK11: COINCO DE COLOMBIA S.A.S. (50%) INGENIERIA MASTER S.A.S. (25%) CONSULTORIA TECNICA DE OBRAS S.A.S. (25%) | AL11: DAVINSON GRAVINI POLO | AM11: 7713151737 | AN11: 5322736268 | AO11: =AM11+AN11 -> 13035888005 | AP11: 1.0364113e+10 | AQ11: 1.0364113e+10 | AR11: 0 | AS11: 0 | AT11: 6.8557953e+08 | AU11: 0 | AV11: 0 | AW11: 1400 Habitantes | AX11: Metros Lineales intervenidos | AY11: Kilometros recuperados por Barrio | AZ11: Tramos viales inaugurados | BA11: Tramites de recibo final y terminacion, cierres de actas de vecindad, pqrs y pendientes en campo | BC11: No
A12: =+A11+1 -> 11 | B12: Obras Públicas | C12: CD-12-2020-2429 | D12: Línea Económica_Ciudad Dinámica | E12: Trasporte | F12: Barrios a la obra | G12: BAO_VII_2429_M11 | H12: Varias | I12: Alboraya - Carrizal - Las Palmas - Primero de Mayo - San Nicolas - Siape - Buenos Aires | J12: - | K12: 10°58'6.7'' N 74°46'52.8'' O | N12: Postcontractual | O12: Terminado | P12: =+AO12+AT12 -> 1.3891374e+10 | Q12: 1 | R12: 1 | S12: =+R12-Q12 -> 0 | T12: {=+_xlfn.IFS($P12<=10000000000,IF(S12>-0.05,"Verde",IF(S12<=-0.1,"Rojo","Amarillo")),$P12>10000000000,IF(S12>-0.03,"Verde",IF(S12<=-0.07,"Rojo","Amarillo")))} -> Verde | U12: 44305 | V12: 44334 | W12: 44442 | X12: 44561 | Y12: 45596 | Z12: =+IF(AND(O12="En_Ejecución",OR(T12="Rojo",T12="Amarillo")),IF(($Y12-(TODAY())<15),"Rojo",IF(($Y12-TODAY())>=45,"Verde","Amarillo")),O12) -> Terminado | AA12: =+IF(AND(Z12="Amarillo",T12="Rojo"),"En_Seguimiento",IF(AND(Z12="Rojo",T12="Amarillo"),"En_Seguimiento",IF(AND(Z12="Rojo",T12="Rojo"),"En_Seguimiento",IF(AND(Z12="Suspendido",T12="Amarillo"),"En_Seguimiento",IF(AND(Z12="Suspendido",T12="Rojo"),"En_Seguimiento","-"))))) -> - | AB12: No | AD12: 45596 | AE12: EDU-366-2021 | AF12: CONSORCIO ATLANTA | AG12: IDC 21 S.A.S. (55%) PROYECTOS DE INGENIERIA Y CONSTRUCCIONES A.R. S.A.S. (40%) AZUL CONSTRUCCIÓN Y MINERIA S.A.S. (5%) | AH12: Ismael Enrique Gomez Prada | AI12: EDU-388-2021 | AJ12: CONSORCIO INTERVIAS BARRANQUILLA | AK12: COMPAÑÍA DE INTERVENTORIAS Y CONSULTORIAS DE LA COSTA S.A.S. (59%) ROCCIA S.A.S. (30%) CGB (10%) INEXIA S.A.S. (1%) | AL12: CARLOS MASS GUERRERO | AM12: 7727867246 | AN12: 5528860714 | AO12: =AM12+AN12 -> 13256727960 | AP12: 11221659834 | AQ12: 11221659834 | AR12: 0 | AS12: 0 | AT12: 6.3464607e+08 | AU12: 0 | AV12: 0 | AW12: 2248 Habitantes | AX12: Metros Lineales intervenidos | AY12: Kilometros recuperados por Barrio | AZ12: Tramos viales inaugurados | BA12: Tramites de recibo final y terminacion, cierres de actas de vecindad, pqrs y pendientes en campo | BC12: No
A13: =+A12+1 -> 12 | B13: Obras Públicas | C13: CD-12-2020-2429 | D13: Línea Económica_Ciudad Dinámica | E13: Trasporte | F13: Barrios a la obra | G13: BAO_VII_2429_M12 | H13: Varias | I13: La Playa - Los Olivos I - Los Olivos II - El Pueblo - La Pradera | J13: - | K13: 10°58'6.7'' N 74°46'52.8'' O | N13: Postcontractual | O13: Liquidado | P13: =+AO13+AT13 -> 8.1375728e+09 | Q13: 1 | R13: 1 | S13: =+R13-Q13 -> 0 | T13: {=+_xlfn.IFS($P13<=10000000000,IF(S13>-0.05,"Verde",IF(S13<=-0.1,"Rojo","Amarillo")),$P13>10000000000,IF(S13>-0.03,"Verde",IF(S13<=-0.07,"Rojo","Amarillo")))} -> Verde | U13: 44305 | V13: 44334 | W13: 44442 | X13: 44561 | Y13: 44772 | Z13: =+IF(AND(O13="En_Ejecución",OR(T13="Rojo",T13="Amarillo")),IF(($Y13-(TODAY())<15),"Rojo",IF(($Y13-TODAY())>=45,"Verde","Amarillo")),O13) -> Liquidado | AA13: =+IF(AND(Z13="Amarillo",T13="Rojo"),"En_Seguimiento",IF(AND(Z13="Rojo",T13="Amarillo"),"En_Seguimiento",IF(AND(Z13="Rojo",T13="Rojo"),"En_Seguimiento",IF(AND(Z13="Suspendido",T13="Amarillo"),"En_Seguimiento",IF(AND(Z13="Suspendido",T13="Rojo"),"En_Seguimiento","-"))))) -> - | AB13: No | AD13: 44772 | AE13: EDU-367-2021 | AF13: CONSORCIO AZUL | AG13: CARLOS ALBERTO ROZO NADER (50%) AZUL CONSTRUCCIÓN Y MINERIA S.A.S. (50%) | AH13: Carlos Alberto Rozo Nader | AI13: EDU-388-2021 | AJ13: CONSORCIO INTERVIAS BARRANQUILLA | AK13: COMPAÑÍA DE INTERVENTORIAS Y CONSULTORIAS DE LA COSTA S.A.S. (59%) ROCCIA S.A.S. (30%) CGB (10%) INEXIA S.A.S. (1%) | AL13: CARLOS MASS GUERRERO | AM13: 7765796823 | AN13: 0 | AO13: =AM13+AN13 -> 7765796823 | AP13: 7526252083 | AQ13: 6925540108 | AR13: 0 | AS13: 0 | AT13: 3.7177594e+08 | AU13: 0 | AV13: 0 | AW13: 1408 Habitantes | AX13: Metros Lineales intervenidos | AY13: Kilometros recuperados por Barrio | AZ13: Tramos viales inaugurados | BA13: ACTIVIDADES FINALIZADAS | BC13: No
A14: =+A13+1 -> 13 | B14: Obras Públicas | C14: CD-12-2024-0002 | D14: Línea Económica_Ciudad Dinámica | E14: Trasporte | F14: Barrios a la obra | G14: BAO_VIII_0002_M1 | H14: =IFERROR(_xlfn.XLOOKUP(I14,[2]Listas!$C$2:$C$202,[2]Listas!$B$2:$B$202),"-") -> VARIAS | I14: VARIOS | J14: - | K14: =CONCATENATE(CONCATENATE( ABS(TRUNC(L14)),"°", TRUNC((ABS(L14)-ABS(TRUNC(L14)))*60),"'", ROUND((((ABS(L14)-ABS(TRUNC(L14)))*60)-TRUNC((ABS(L14)-ABS(TRUNC(L14)))*60))*60,0),"""", IF(L14<0,"O","E") ),", ",CONCATENATE( ABS(TRUNC(M14)),"°", TRUNC((ABS(M14)-ABS(TRUNC(M14)))*60),"'", ROUND((((ABS(M14)-ABS(TRUNC(M14)))*60)-TRUNC((ABS(M14)-ABS(TRUNC(M14)))*60))*60,0),"""", IF(M14<0,"S","N") )) -> 0°0'0"E, 0°0'0"N | L14: 0 | M14: 0 | N14: Contractual | O14: En_Ejecución | P14: =AO14+AT14 -> 5.5806512e+08 | Q14: 0.9268 | R14: 0.6111 | S14: =+R14-Q14 -> -0.3157 | T14: {=+_xlfn.IFS($P14<=10000000000,IF(S14>-0.05,"Verde",IF(S14<=-0.1,"Rojo","Amarillo")),$P14>10000000000,IF(S14>-0.03,"Verde",IF(S14<=-0.07,"Rojo","Amarillo")))} -> Rojo | U14: 45373 | V14: 45391 | W14: 45314 | X14: 45930 | Y14: 45930 | Z14: =+IF(AND(O14="En_Ejecución",OR(T14="Rojo",T14="Amarillo")),IF(($Y14-(TODAY())<15),"Rojo",IF(($Y14-TODAY())>=45,"Verde","Amarillo")),O14) -> Rojo | AA14: =+IF(AND(Z14="Amarillo",T14="Rojo"),"En_Seguimiento",IF(AND(Z14="Rojo",T14="Amarillo"),"En_Seguimiento",IF(AND(Z14="Rojo",T14="Rojo"),"En_Seguimiento",IF(AND(Z14="Suspendido",T14="Amarillo"),"En_Seguimiento",IF(AND(Z14="Suspendido",T14="Rojo"),"En_Seguimiento","-"))))) -> En_Seguimiento | AB14: No | AC14: - | AD14: 45930 | AE14: SA-EDU-021-2024 | AF14: CONSORCIO VIAS BAREM | AG14: BARMAR CONSTRUCCIONES S.A.S (NIT 901.234.686-5) 90% EMIRO CARLOS BARGUIL CUBILLOS (CC 78.034.207) 10% | AH14: EMIRO CARLOS BARGUIL CUBILLOS | AI14: CD-12-2024-0002 | AJ14: CONSORCIO DS | AK14: SESAC S.A (NIT 800.064.761-3) 90% DEIGMA S.A.S (NIT 900.498.688-9) 10% | AL14: ALEJANDRO ALBA QUINTERO | AM14: 5.5806512e+08 | AN14: 0 | AO14: =AM14+AN14 -> 5.5806512e+08 | AP14: 0 | AQ14: 0 | AR14: 0 | AS14: 0 | AT14: =AR14+AS14 -> 0 | AU14: 0 | AV14: 0 | AW14: NO APLICA | AX14: Metros Lineales intervenidos | AY14: Kilometros recuperados por Barrio | AZ14: Tramos viales inaugurados | BA14: Valor estimado por metro lineal del tramo, se realizan actividades de socializaciones en campo con la comunidad y levantamiento de actas de vecindad | BB14: - | BC14: No
A15: =+A14+1 -> 14 | B15: Obras Públicas | C15: CD-12-2024-0002 | D15: Línea Económica_Ciudad Dinámica | E15: Trasporte | F15: Barrios a la obra | G15: BAO_VIII_0002_M2 | H15: =IFERROR(_xlfn.XLOOKUP(I15,[2]Listas!$C$2:$C$202,[2]Listas!$B$2:$B$202),"-") -> VARIAS | I15: VARIOS | J15: - | K15: =CONCATENATE(CONCATENATE( ABS(TRUNC(L15)),"°", TRUNC((ABS(L15)-ABS(TRUNC(L15)))*60),"'", ROUND((((ABS(L15)-ABS(TRUNC(L15)))*60)-TRUNC((ABS(L15)-ABS(TRUNC(L15)))*60))*60,0),"""", IF(L15<0,"O","E") ),", ",CONCATENATE( ABS(TRUNC(M15)),"°", TRUNC((ABS(M15)-ABS(TRUNC(M15)))*60),"'", ROUND((((ABS(M15)-ABS(TRUNC(M15)))*60)-TRUNC((ABS(M15)-ABS(TRUNC(M15)))*60))*60,0),"""", IF(M15<0,"S","N") )) -> 0°0'0"E, 0°0'0"N | L15: 0 | M15: 0 | N15: Contractual | O15: En_Ejecución | P15: =AO15+AT15 -> 3.5143717e+08 | Q15: 0.9268 | R15: 0.4959 | S15: 0 | T15: {=+_xlfn.IFS($P15<=10000000000,IF(S15>-0.05,"Verde",IF(S15<=-0.1,"Rojo","Amarillo")),$P15>10000000000,IF(S15>-0.03,"Verde",IF(S15<=-0.07,"Rojo","Amarillo")))} -> Verde | U15: 45373 | V15: 45391 | W15: 45314 | X15: 45930 | Y15: 45930 | Z15: =+IF(AND(O15="En_Ejecución",OR(T15="Rojo",T15="Amarillo")),IF(($Y15-(TODAY())<15),"Rojo",IF(($Y15-TODAY())>=45,"Verde","Amarillo")),O15) -> En_Ejecución | AA15: - | AB15: No | AC15: - | AD15: 45930 | AE15: SA-EDU-007-2024 | AF15: CONSORCIO SAN CHARBEL EDU | AG15: COTES & COTES S.A.S (NIT 900.336.724-1) 70% REDES VIALES Y CONSTRUCCIONES S.A.S (NIT 900.606.651-6) 10% FUNDACIÓN OCEANIA 2030 (NIT 901.378.017-6) 10% CONSTRUCCIONES ELITE 2000 S.A.S (NIT 901.636.617-2) 10% | AH15: CARLOS KARLO COTES MADERA | AI15: CD-12-2024-0002 | AJ15: CONSORCIO DS | AK15: SESAC S.A (NIT 800.064.761-3) 90% DEIGMA S.A.S (NIT 900.498.688-9) 10% | AL15: ALEJANDRO ALBA QUINTERO | AM15: 3.5143717e+08 | AN15: 0 | AO15: =AM15+AN15 -> 3.5143717e+08 | AP15: 0 | AQ15: 0 | AR15: 0 | AS15: 0 | AT15: 0 | AU15: 0 | AV15: 0 | AW15: NO APLICA | AX15: Metros Lineales intervenidos | AY15: Kilometros recuperados por Barrio | AZ15: Tramos viales inaugurados | BA15: Valor estimado por metro lineal del tramo, se realizan actividades de socializaciones en campo con la comunidad y levantamiento de actas de vecindad | BB15: - | BC15: No
A16: =+A15+1 -> 15 | B16: Obras Públicas | C16: CD-12-2024-0002 | D16: Línea Económica_Ciudad Dinámica | E16: Trasporte | F16: Barrios a la obra | G16: BAO_VIII_0002_M3 | H16: =IFERROR(_xlfn.XLOOKUP(I16,[2]Listas!$C$2:$C$202,[2]Listas!$B$2:$B$202),"-") -> VARIAS | I16: VARIOS | J16: - | K16: =CONCATENATE(CONCATENATE( ABS(TRUNC(L16)),"°", TRUNC((ABS(L16)-ABS(TRUNC(L16)))*60),"'", ROUND((((ABS(L16)-ABS(TRUNC(L16)))*60)-TRUNC((ABS(L16)-ABS(TRUNC(L16)))*60))*60,0),"""", IF(L16<0,"O","E") ),", ",CONCATENATE( ABS(TRUNC(M16)),"°", TRUNC((ABS(M16)-ABS(TRUNC(M16)))*60),"'", ROUND((((ABS(M16)-ABS(TRUNC(M16)))*60)-TRUNC((ABS(M16)-ABS(TRUNC(M16)))*60))*60,0),"""", IF(M16<0,"S","N") )) -> 0°0'0"E, 0°0'0"N | L16: 0 | M16: 0 | N16: Contractual | O16: En_Ejecución | P16: =AO16+AT16 -> 4.254862e+08 | Q16: 0.9268 | R16: 0.3998 | S16: =+R16-Q16 -> -0.527 | T16: {=+_xlfn.IFS($P16<=10000000000,IF(S16>-0.05,"Verde",IF(S16<=-0.1,"Rojo","Amarillo")),$P16>10000000000,IF(S16>-0.03,"Verde",IF(S16<=-0.07,"Rojo","Amarillo")))} -> Rojo | U16: 45373 | V16: 45391 | W16: 45314 | X16: 45930 | Y16: 45930 | Z16: =+IF(AND(O16="En_Ejecución",OR(T16="Rojo",T16="Amarillo")),IF(($Y16-(TODAY())<15),"Rojo",IF(($Y16-TODAY())>=45,"Verde","Amarillo")),O16) -> Rojo | AA16: =+IF(AND(Z16="Amarillo",T16="Rojo"),"En_Seguimiento",IF(AND(Z16="Rojo",T16="Amarillo"),"En_Seguimiento",IF(AND(Z16="Rojo",T16="Rojo"),"En_Seguimiento",IF(AND(Z16="Suspendido",T16="Amarillo"),"En_Seguimiento",IF(AND(Z16="Suspendido",T16="Rojo"),"En_Seguimiento","-"))))) -> En_Seguimiento | AB16: No | AC16: - | AD16: 45930 | AE16: SA-EDU-008-2024 | AF16: CONSORCIO VIAS URBANAS 2024 | AG16: PLANETA PROYECTOS Y OBRAS S.A.S (NIT 901.020.571-8) 90% R&D INGENIERIA Y ARQUITECTURA S.A.S (NIT 900.554.914-9) 10% | AH16: CARLOS JOSÉ MARTÍNEZ HERNÁNDEZ | AI16: CD-12-2024-0002 | AJ16: CONSORCIO DS | AK16: SESAC S.A (NIT 800.064.761-3) 90% DEIGMA S.A.S (NIT 900.498.688-9) 10% | AL16: ALEJANDRO ALBA QUINTERO | AM16: 4.254862e+08 | AN16: 0 | AO16: =AM16+AN16 -> 4.254862e+08 | AP16: 0 | AQ16: 0 | AR16: 0 | AS16: 0 | AT16: =AR16+AS16 -> 0 | AU16: 0 | AV16: 0 | AW16: NO APLICA | AX16: Metros Lineales intervenidos | AY16: Kilometros recuperados por Barrio | AZ16: Tramos viales inaugurados | BA16: Valor estimado por metro lineal del tramo, se realizan actividades de socializaciones en campo con la comunidad y levantamiento de actas de vecindad | BB16: - | BC16: No
A17: =+A16+1 -> 16 | B17: Obras Públicas | C17: CD-12-2024-0002 | D17: Línea Económica_Ciudad Dinámica | E17: Trasporte | F17: Barrios a la obra | G17: BAO_VIII_0002_M4 | H17: =IFERROR(_xlfn.XLOOKUP(I17,[2]Listas!$C$2:$C$202,[2]Listas!$B$2:$B$202),"-") -> VARIAS | I17: VARIOS | J17: - | K17: =CONCATENATE(CONCATENATE( ABS(TRUNC(L17)),"°", TRUNC((ABS(L17)-ABS(TRUNC(L17)))*60),"'", ROUND((((ABS(L17)-ABS(TRUNC(L17)))*60)-TRUNC((ABS(L17)-ABS(TRUNC(L17)))*60))*60,0),"""", IF(L17<0,"O","E") ),", ",CONCATENATE( ABS(TRUNC(M17)),"°", TRUNC((ABS(M17)-ABS(TRUNC(M17)))*60),"'", ROUND((((ABS(M17)-ABS(TRUNC(M17)))*60)-TRUNC((ABS(M17)-ABS(TRUNC(M17)))*60))*60,0),"""", IF(M17<0,"S","N") )) -> 0°0'0"E, 0°0'0"N | L17: 0 | M17: 0 | N17: Contractual | O17: En_Ejecución | P17: =AO17+AT17 -> 6806556121 | Q17: 0.8925 | R17: 0.9718 | S17: =+R17-Q17 -> 0.0793 | T17: {=+_xlfn.IFS($P17<=10000000000,IF(S17>-0.05,"Verde",IF(S17<=-0.1,"Rojo","Amarillo")),$P17>10000000000,IF(S17>-0.03,"Verde",IF(S17<=-0.07,"Rojo","Amarillo")))} -> Verde | U17: 45373 | V17: 45391 | W17: 45314 | X17: 45930 | Y17: 45930 | Z17: =+IF(AND(O17="En_Ejecución",OR(T17="Rojo",T17="Amarillo")),IF(($Y17-(TODAY())<15),"Rojo",IF(($Y17-TODAY())>=45,"Verde","Amarillo")),O17) -> En_Ejecución | AA17: =+IF(AND(Z17="Amarillo",T17="Rojo"),"En_Seguimiento",IF(AND(Z17="Rojo",T17="Amarillo"),"En_Seguimiento",IF(AND(Z17="Rojo",T17="Rojo"),"En_Seguimiento",IF(AND(Z17="Suspendido",T17="Amarillo"),"En_Seguimiento",IF(AND(Z17="Suspendido",T17="Rojo"),"En_Seguimiento","-"))))) -> - | AB17: No | AC17: - | AD17: 45930 | AE17: SA-EDU-009-2024 | AF17: CONSORCIO G3 PAVIMENTAR BARRANQUILLA 24 | AG17: CONSTRUCCIONES Y DISEÑOS STEVENSON HERMANOS S.A.S Y/O CONDIS S.A.S (NIT 802.017.107-3) 45% MOVICONTRUCCIONES S.A.S (NIT 900.068.501-6) 45% CONSTRUCCIONES E INTERVENTORIA LEGAL S.A.S (NIT 900.606.675-8) 10% | AH17: IVAN ENRIQUE STEVENSON DEL VECCHIO | AI17: CD-12-2024-0002 | AJ17: CONSORCIO DS | AK17: SESAC S.A (NIT 800.064.761-3) 90% DEIGMA S.A.S (NIT 900.498.688-9) 10% | AL17: ALEJANDRO ALBA QUINTERO | AM17: 6806556121 | AN17: 0 | AO17: =AM17+AN17 -> 6806556121 | AP17: 0 | AQ17: 0 | AR17: 0 | AS17: 0 | AT17: =AR17+AS17 -> 0 | AU17: 0 | AV17: 0 | AW17: NO APLICA | AX17: Metros Lineales intervenidos | AY17: Kilometros recuperados por Barrio | AZ17: Tramos viales inaugurados | BA17: Valor estimado por metro lineal del tramo, se realizan actividades de socializaciones en campo con la comunidad y levantamiento de actas de vecindad | BB17: - | BC17: No
A18: =+A17+1 -> 17 | B18: Obras Públicas | C18: CD-12-2024-0002 | D18: Línea Económica_Ciudad Dinámica | E18: Trasporte | F18: Barrios a la obra | G18: BAO_VIII_0002_M5 | H18: =IFERROR(_xlfn.XLOOKUP(I18,[2]Listas!$C$2:$C$202,[2]Listas!$B$2:$B$202),"-") -> VARIAS | I18: VARIOS | J18: - | K18: =CONCATENATE(CONCATENATE( ABS(TRUNC(L18)),"°", TRUNC((ABS(L18)-ABS(TRUNC(L18)))*60),"'", ROUND((((ABS(L18)-ABS(TRUNC(L18)))*60)-TRUNC((ABS(L18)-ABS(TRUNC(L18)))*60))*60,0),"""", IF(L18<0,"O","E") ),", ",CONCATENATE( ABS(TRUNC(M18)),"°", TRUNC((ABS(M18)-ABS(TRUNC(M18)))*60),"'", ROUND((((ABS(M18)-ABS(TRUNC(M18)))*60)-TRUNC((ABS(M18)-ABS(TRUNC(M18)))*60))*60,0),"""", IF(M18<0,"S","N") )) -> 0°0'0"E, 0°0'0"N | L18: 0 | M18: 0 | N18: Contractual | O18: En_Ejecución | P18: =AO18+AT18 -> 215591272 | Q18: 0.841 | R18: 0.5995 | S18: =+R18-Q18 -> -0.2415 | T18: {=+_xlfn.IFS($P18<=10000000000,IF(S18>-0.05,"Verde",IF(S18<=-0.1,"Rojo","Amarillo")),$P18>10000000000,IF(S18>-0.03,"Verde",IF(S18<=-0.07,"Rojo","Amarillo")))} -> Rojo | U18: 45373 | V18: 45391 | W18: 45314 | X18: 45930 | Y18: 45930 | Z18: =+IF(AND(O18="En_Ejecución",OR(T18="Rojo",T18="Amarillo")),IF(($Y18-(TODAY())<15),"Rojo",IF(($Y18-TODAY())>=45,"Verde","Amarillo")),O18) -> Rojo | AA18: =+IF(AND(Z18="Amarillo",T18="Rojo"),"En_Seguimiento",IF(AND(Z18="Rojo",T18="Amarillo"),"En_Seguimiento",IF(AND(Z18="Rojo",T18="Rojo"),"En_Seguimiento",IF(AND(Z18="Suspendido",T18="Amarillo"),"En_Seguimiento",IF(AND(Z18="Suspendido",T18="Rojo"),"En_Seguimiento","-"))))) -> En_Seguimiento | AB18: No | AC18: - | AD18: 45930 | AE18: SA-EDU-010-2024 | AF18: CONSORCIO EDUBAR 2024 | AG18: OBRAS INTERVENTORIAS Y SUMINISTROS S.A.S (NIT 900.974.081-0) 90% INGENIERIA RYD S.A.S (NIT 901.499.915-4) 10% | AH18: CARMELO FAILLACE SAID | AI18: CD-12-2024-0002 | AJ18: CONSORCIO DS | AK18: SESAC S.A (NIT 800.064.761-3) 90% DEIGMA S.A.S (NIT 900.498.688-9) 10% | AL18: ALEJANDRO ALBA QUINTERO | AM18: 215591272 | AN18: 0 | AO18: =AM18+AN18 -> 215591272 | AP18: 0 | AQ18: 0 | AR18: 0 | AS18: 0 | AT18: =AR18+AS18 -> 0 | AU18: 0 | AV18: 0 | AW18: NO APLICA | AX18: Metros Lineales intervenidos | AY18: Kilometros recuperados por Barrio | AZ18: Tramos viales inaugurados | BA18: Se realizaron actividades de pavimentacion en concreto reforzado, andenes y bordillos. | BB18: - | BC18: No
A19: =+A18+1 -> 18 | B19: Obras Públicas | C19: CD-12-2024-0002 | D19: Línea Económica_Ciudad Dinámica | E19: Trasporte | F19: Barrios a la obra | G19: BAO_VIII_0002_M6 | H19: =IFERROR(_xlfn.XLOOKUP(I19,[2]Listas!$C$2:$C$202,[2]Listas!$B$2:$B$202),"-") -> VARIAS | I19: VARIOS | J19: - | K19: =CONCATENATE(CONCATENATE( ABS(TRUNC(L19)),"°", TRUNC((ABS(L19)-ABS(TRUNC(L19)))*60),"'", ROUND((((ABS(L19)-ABS(TRUNC(L19)))*60)-TRUNC((ABS(L19)-ABS(TRUNC(L19)))*60))*60,0),"""", IF(L19<0,"O","E") ),", ",CONCATENATE( ABS(TRUNC(M19)),"°", TRUNC((ABS(M19)-ABS(TRUNC(M19)))*60),"'", ROUND((((ABS(M19)-ABS(TRUNC(M19)))*60)-TRUNC((ABS(M19)-ABS(TRUNC(M19)))*60))*60,0),"""", IF(M19<0,"S","N") )) -> 0°0'0"E, 0°0'0"N | L19: 0 | M19: 0 | N19: Contractual | O19: En_Ejecución | P19: =AO19+AT19 -> 9018274387 | Q19: 0.8659 | R19: 0.8081 | S19: =+R19-Q19 -> -0.0578 | T19: {=+_xlfn.IFS($P19<=10000000000,IF(S19>-0.05,"Verde",IF(S19<=-0.1,"Rojo","Amarillo")),$P19>10000000000,IF(S19>-0.03,"Verde",IF(S19<=-0.07,"Rojo","Amarillo")))} -> Amarillo | U19: 45373 | V19: 45391 | W19: 45314 | X19: 45930 | Y19: 45930 | Z19: =+IF(AND(O19="En_Ejecución",OR(T19="Rojo",T19="Amarillo")),IF(($Y19-(TODAY())<15),"Rojo",IF(($Y19-TODAY())>=45,"Verde","Amarillo")),O19) -> Rojo | AA19: =+IF(AND(Z19="Amarillo",T19="Rojo"),"En_Seguimiento",IF(AND(Z19="Rojo",T19="Amarillo"),"En_Seguimiento",IF(AND(Z19="Rojo",T19="Rojo"),"En_Seguimiento",IF(AND(Z19="Suspendido",T19="Amarillo"),"En_Seguimiento",IF(AND(Z19="Suspendido",T19="Rojo"),"En_Seguimiento","-"))))) -> En_Seguimiento | AB19: No | AC19: - | AD19: 45930 | AE19: SA-EDU-023-2024 | AF19: CONSORCIO VIAS QUILLA | AG19: SOSDOM S.A.S (NIT 829.001.805-4) 50% RE-INGENIERIA S.A.S (NIT 900.206.366-0) 50% | AH19: SANTIAGO ANDRES DOMINGUEZ CAÑA | AI19: CD-12-2024-0002 | AJ19: PROYECTOS E INTERVENTORIAS S.A.S PI S.A.S | AK19: PROYECTOS E INTERVENTORIAS S.A.S PI S.A.S | AL19: WILSON GIOVANNI URREA URREA | AM19: 9018274387 | AN19: 0 | AO19: =AM19+AN19 -> 9018274387 | AP19: 0 | AQ19: 0 | AR19: 0 | AS19: 0 | AT19: =AR19+AS19 -> 0 | AU19: 0 | AV19: 0 | AW19: NO APLICA | AX19: Metros Lineales intervenidos | AY19: Kilometros recuperados por Barrio | AZ19: - | BA19: Se realizan actividades de socializaciones en campo con la comunidad | BB19: - | BC19: No
A20: =+A19+1 -> 19 | B20: Obras Públicas | C20: CD-12-2024-0002 | D20: Línea Económica_Ciudad Dinámica | E20: Trasporte | F20: Barrios a la obra | G20: BAO_VIII_0002_M7 | H20: =IFERROR(_xlfn.XLOOKUP(I20,[2]Listas!$C$2:$C$202,[2]Listas!$B$2:$B$202),"-") -> VARIAS | I20: VARIOS | J20: - | K20: =CONCATENATE(CONCATENATE( ABS(TRUNC(L20)),"°", TRUNC((ABS(L20)-ABS(TRUNC(L20)))*60),"'", ROUND((((ABS(L20)-ABS(TRUNC(L20)))*60)-TRUNC((ABS(L20)-ABS(TRUNC(L20)))*60))*60,0),"""", IF(L20<0,"O","E") ),", ",CONCATENATE( ABS(TRUNC(M20)),"°", TRUNC((ABS(M20)-ABS(TRUNC(M20)))*60),"'", ROUND((((ABS(M20)-ABS(TRUNC(M20)))*60)-TRUNC((ABS(M20)-ABS(TRUNC(M20)))*60))*60,0),"""", IF(M20<0,"S","N") )) -> 0°0'0"E, 0°0'0"N | L20: 0 | M20: 0 | N20: Contractual | O20: En_Ejecución | P20: =AO20+AT20 -> 9186635876 | Q20: 1 | R20: 0.6363 | S20: =+R20-Q20 -> -0.3637 | T20: {=+_xlfn.IFS($P20<=10000000000,IF(S20>-0.05,"Verde",IF(S20<=-0.1,"Rojo","Amarillo")),$P20>10000000000,IF(S20>-0.03,"Verde",IF(S20<=-0.07,"Rojo","Amarillo")))} -> Rojo | U20: 45373 | V20: 45391 | W20: 45314 | X20: 45930 | Y20: 45930 | Z20: =+IF(AND(O20="En_Ejecución",OR(T20="Rojo",T20="Amarillo")),IF(($Y20-(TODAY())<15),"Rojo",IF(($Y20-TODAY())>=45,"Verde","Amarillo")),O20) -> Rojo | AA20: =+IF(AND(Z20="Amarillo",T20="Rojo"),"En_Seguimiento",IF(AND(Z20="Rojo",T20="Amarillo"),"En_Seguimiento",IF(AND(Z20="Rojo",T20="Rojo"),"En_Seguimiento",IF(AND(Z20="Suspendido",T20="Amarillo"),"En_Seguimiento",IF(AND(Z20="Suspendido",T20="Rojo"),"En_Seguimiento","-"))))) -> En_Seguimiento | AB20: No | AC20: - | AD20: 45930 | AE20: SA-EDU-004-2024 | AF20: CONSORCIO COMPETITIVIDAD BARRANQUILLA | AG20: ESDRAS MD INGENIERIA S.A.S (NIT 900.816.446-2) 40% ALVARO HERNANDO CALDERON TORO (CC 16.625.689) 60% | AH20: ALVARO HERNANDO CALDERON TORO | AI20: CD-12-2024-0002 | AJ20: PROYECTOS E INTERVENTORIAS S.A.S PI S.A.S | AK20: PROYECTOS E INTERVENTORIAS S.A.S PI S.A.S | AL20: WILSON GIOVANNI URREA URREA | AM20: 9186635876 | AN20: 0 | AO20: =AM20+AN20 -> 9186635876 | AP20: 0 | AQ20: 0 | AR20: 0 | AS20: 0 | AT20: =AR20+AS20 -> 0 | AU20: 0 | AV20: 0 | AW20: NO APLICA | AX20: Espacio Publico recuperado | AY20: Area recuperada para vehiculos | AZ20: - | BA20: - | BB20: - | BC20: No
A21: =+A20+1 -> 20 | B21: Obras Públicas | C21: CD-12-2024-0002 | D21: Línea Económica_Ciudad Dinámica | E21: Trasporte | F21: Barrios a la obra | G21: BAO_VIII_0002_M8 | H21: =IFERROR(_xlfn.XLOOKUP(I21,[2]Listas!$C$2:$C$202,[2]Listas!$B$2:$B$202),"-") -> VARIAS | I21: VARIOS | J21: - | K21: =CONCATENATE(CONCATENATE( ABS(TRUNC(L21)),"°", TRUNC((ABS(L21)-ABS(TRUNC(L21)))*60),"'", ROUND((((ABS(L21)-ABS(TRUNC(L21)))*60)-TRUNC((ABS(L21)-ABS(TRUNC(L21)))*60))*60,0),"""", IF(L21<0,"O","E") ),", ",CONCATENATE( ABS(TRUNC(M21)),"°", TRUNC((ABS(M21)-ABS(TRUNC(M21)))*60),"'", ROUND((((ABS(M21)-ABS(TRUNC(M21)))*60)-TRUNC((ABS(M21)-ABS(TRUNC(M21)))*60))*60,0),"""", IF(M21<0,"S","N") )) -> 0°0'0"E, 0°0'0"N | L21: 0 | M21: 0 | N21: Contractual | O21: En_Ejecución | P21: =AO21+AT21 -> 12557965286 | Q21: 1 | R21: 0.8063 | S21: =+R21-Q21 -> -0.1937 | T21: {=+_xlfn.IFS($P21<=10000000000,IF(S21>-0.05,"Verde",IF(S21<=-0.1,"Rojo","Amarillo")),$P21>10000000000,IF(S21>-0.03,"Verde",IF(S21<=-0.07,"Rojo","Amarillo")))} -> Rojo | U21: 45373 | V21: 45391 | W21: 45314 | X21: 45930 | Y21: 45930 | Z21: =+IF(AND(O21="En_Ejecución",OR(T21="Rojo",T21="Amarillo")),IF(($Y21-(TODAY())<15),"Rojo",IF(($Y21-TODAY())>=45,"Verde","Amarillo")),O21) -> Rojo | AA21: =+IF(AND(Z21="Amarillo",T21="Rojo"),"En_Seguimiento",IF(AND(Z21="Rojo",T21="Amarillo"),"En_Seguimiento",IF(AND(Z21="Rojo",T21="Rojo"),"En_Seguimiento",IF(AND(Z21="Suspendido",T21="Amarillo"),"En_Seguimiento",IF(AND(Z21="Suspendido",T21="Rojo"),"En_Seguimiento","-"))))) -> En_Seguimiento | AB21: No | AC21: - | AD21: 45930 | AE21: SA-EDU-011-2024 | AF21: CONSORCIO DP 2024 | AG21: DONADO ARCE Y CIA S.A.S (NIT 890.111.275-4) 90% PACANO S.A.S (NIT 900.565.619-8) 10% | AH21: ROBERTO CARLO DONADO ARCE | AI21: CD-12-2024-0002 | AJ21: PROYECTOS E INTERVENTORIAS S.A.S PI S.A.S | AK21: PROYECTOS E INTERVENTORIAS S.A.S PI S.A.S | AL21: WILSON GIOVANNI URREA URREA | AM21: 12557965286 | AN21: 0 | AO21: =AM21+AN21 -> 12557965286 | AP21: 0 | AQ21: 0 | AR21: 0 | AS21: 0 | AT21: =AR21+AS21 -> 0 | AU21: 0 | AV21: 0 | AW21: Se Beneficia el sector de la salud, zonas educativas y puntos comerciales | AX21: Espacio Publico recuperado | AY21: Area recuperada para vehiculos | AZ21: - | BA21: Se realizan actividades de socializaciones en campo con la comunidad | BB21: - | BC21: No
A22: =+A21+1 -> 21 | B22: Obras Públicas | C22: CD-12-2024-0002 | D22: Línea Económica_Ciudad Dinámica | E22: Trasporte | F22: Barrios a la obra | G22: BAO_VIII_0002_M9 | H22: =IFERROR(_xlfn.XLOOKUP(I22,[2]Listas!$C$2:$C$202,[2]Listas!$B$2:$B$202),"-") -> VARIAS | I22: VARIOS | J22: - | K22: =CONCATENATE(CONCATENATE( ABS(TRUNC(L22)),"°", TRUNC((ABS(L22)-ABS(TRUNC(L22)))*60),"'", ROUND((((ABS(L22)-ABS(TRUNC(L22)))*60)-TRUNC((ABS(L22)-ABS(TRUNC(L22)))*60))*60,0),"""", IF(L22<0,"O","E") ),", ",CONCATENATE( ABS(TRUNC(M22)),"°", TRUNC((ABS(M22)-ABS(TRUNC(M22)))*60),"'", ROUND((((ABS(M22)-ABS(TRUNC(M22)))*60)-TRUNC((ABS(M22)-ABS(TRUNC(M22)))*60))*60,0),"""", IF(M22<0,"S","N") )) -> 0°0'0"E, 0°0'0"N | L22: 0 | M22: 0 | N22: Contractual | O22: En_Ejecución | P22: =AO22+AT22 -> 12058626643 | Q22: 0.8451 | R22: 0.7444 | S22: =+R22-Q22 -> -0.1007 | T22: {=+_xlfn.IFS($P22<=10000000000,IF(S22>-0.05,"Verde",IF(S22<=-0.1,"Rojo","Amarillo")),$P22>10000000000,IF(S22>-0.03,"Verde",IF(S22<=-0.07,"Rojo","Amarillo")))} -> Rojo | U22: 45373 | V22: 45391 | W22: 45314 | X22: 45930 | Y22: 45930 | Z22: =+IF(AND(O22="En_Ejecución",OR(T22="Rojo",T22="Amarillo")),IF(($Y22-(TODAY())<15),"Rojo",IF(($Y22-TODAY())>=45,"Verde","Amarillo")),O22) -> Rojo | AA22: =+IF(AND(Z22="Amarillo",T22="Rojo"),"En_Seguimiento",IF(AND(Z22="Rojo",T22="Amarillo"),"En_Seguimiento",IF(AND(Z22="Rojo",T22="Rojo"),"En_Seguimiento",IF(AND(Z22="Suspendido",T22="Amarillo"),"En_Seguimiento",IF(AND(Z22="Suspendido",T22="Rojo"),"En_Seguimiento","-"))))) -> En_Seguimiento | AB22: No | AC22: - | AD22: 45930 | AE22: SA-EDU-005-2024 | AF22: CONSORCIO DESARROLLO VIAL BARRANQUILLA | AG22: CONGLOMERADOTECNICO COLOMBIANO S.A.S (NIT 802.005.436-1) 90% JMD INGENIERIA DE PROYECTOS S.A.S (NIT 900.436.384-1) 10% | AI22: CD-12-2024-0002 | AJ22: PROYECTOS E INTERVENTORIAS S.A.S PI S.A.S | AK22: PROYECTOS E INTERVENTORIAS S.A.S PI S.A.S | AL22: WILSON GIOVANNI URREA URREA | AM22: 12058626643 | AN22: 0 | AO22: =AM22+AN22 -> 12058626643 | AP22: 0 | AQ22: 0 | AR22: 0 | AS22: 0 | AT22: =AR22+AS22 -> 0 | AU22: 0 | AV22: 0 | AW22: Se Beneficia el sector de la salud, zonas educativas y puntos comerciales | AX22: Espacio Publico recuperado | AY22: Area recuperada para vehiculos | AZ22: - | BA22: Se realizan actividades de socializaciones en campo con la comunidad | BB22: - | BC22: No
A23: =+A22+1 -> 22 | B23: Obras Públicas | C23: LP-026-2024 | D23: Línea Económica_Ciudad Dinámica | E23: Trasporte | F23: Barrios a la obra | G23: BAO_IX_VN_M1 | H23: =IFERROR(_xlfn.XLOOKUP(I23,[2]Listas!$C$2:$C$202,[2]Listas!$B$2:$B$202),"-") -> VARIAS | I23: VARIOS | J23: - | K23: =CONCATENATE(CONCATENATE( ABS(TRUNC(L23)),"°", TRUNC((ABS(L23)-ABS(TRUNC(L23)))*60),"'", ROUND((((ABS(L23)-ABS(TRUNC(L23)))*60)-TRUNC((ABS(L23)-ABS(TRUNC(L23)))*60))*60,0),"""", IF(L23<0,"O","E") ),", ",CONCATENATE( ABS(TRUNC(M23)),"°", TRUNC((ABS(M23)-ABS(TRUNC(M23)))*60),"'", ROUND((((ABS(M23)-ABS(TRUNC(M23)))*60)-TRUNC((ABS(M23)-ABS(TRUNC(M23)))*60))*60,0),"""", IF(M23<0,"S","N") )) -> 0°0'0"E, 0°0'0"N | L23: 0 | M23: 0 | N23: Contractual | O23: En_Ejecución | P23: =+AO23+AT23 -> 52085450531 | Q23: 0 | R23: 0.2471 | S23: =+R23-Q23 -> 0.2471 | T23: {=+_xlfn.IFS($P23<=10000000000,IF(S23>-0.05,"Verde",IF(S23<=-0.1,"Rojo","Amarillo")),$P23>10000000000,IF(S23>-0.03,"Verde",IF(S23<=-0.07,"Rojo","Amarillo")))} -> Verde | U23: 45707 | V23: 45744 | W23: 45789 | X23: 46335 | Y23: 46335 | Z23: =+IF(AND(O23="En_Ejecución",OR(T23="Rojo",T23="Amarillo")),IF(($Y23-(TODAY())<15),"Rojo",IF(($Y23-TODAY())>=45,"Verde","Amarillo")),O23) -> En_Ejecución | AA23: =+IF(AND(Z23="Amarillo",T23="Rojo"),"En_Seguimiento",IF(AND(Z23="Rojo",T23="Amarillo"),"En_Seguimiento",IF(AND(Z23="Rojo",T23="Rojo"),"En_Seguimiento",IF(AND(Z23="Suspendido",T23="Amarillo"),"En_Seguimiento",IF(AND(Z23="Suspendido",T23="Rojo"),"En_Seguimiento","-"))))) -> - | AB23: No | AC23: - | AD23: 46335 | AE23: LP-026-2024 LOTE 1 | AF23: CONSORCIO VIAS URBANAS BQ | AG23: CONVIAS: 90% (NIT 802.008.095-5) ENGENIERIA S.A.S (NIT 900.595.646-5) 10% | AH23: LUIS FRANCISCO OVALLE LLINAS | AI23: CD-12-2025-3646 | AJ23: CONSORCIO DS | AK23: N/A | AL23: N/A | AM23: 52085450531 | AO23: =AM23+AN23 -> 52085450531 | AP23: 10057307073 | AW23: NO APLICA | AX23: Km por Intervenir: 16.83 Km Intervenidos: 1.17 | AY23: Área por Intervenir: 10.13 Área Intervenida: 5.69 | AZ23: - | BA23: - | BB23: - | BC23: No
A24: =+A23+1 -> 23 | B24: Obras Públicas | C24: LP-026-2024 | D24: Línea Económica_Ciudad Dinámica | E24: Trasporte | F24: Barrios a la obra | G24: BAO_IX_VN_M2 | H24: =IFERROR(_xlfn.XLOOKUP(I24,[2]Listas!$C$2:$C$202,[2]Listas!$B$2:$B$202),"-") -> VARIAS | I24: VARIOS | J24: - | K24: =CONCATENATE(CONCATENATE( ABS(TRUNC(L24)),"°", TRUNC((ABS(L24)-ABS(TRUNC(L24)))*60),"'", ROUND((((ABS(L24)-ABS(TRUNC(L24)))*60)-TRUNC((ABS(L24)-ABS(TRUNC(L24)))*60))*60,0),"""", IF(L24<0,"O","E") ),", ",CONCATENATE( ABS(TRUNC(M24)),"°", TRUNC((ABS(M24)-ABS(TRUNC(M24)))*60),"'", ROUND((((ABS(M24)-ABS(TRUNC(M24)))*60)-TRUNC((ABS(M24)-ABS(TRUNC(M24)))*60))*60,0),"""", IF(M24<0,"S","N") )) -> 0°0'0"E, 0°0'0"N | L24: 0 | M24: 0 | N24: Contractual | O24: En_Ejecución | P24: =+AO24+AT24 -> 52033303778 | Q24: 0 | R24: 0.0742 | S24: =+R24-Q24 -> 0.0742 | T24: {=+_xlfn.IFS($P24<=10000000000,IF(S24>-0.05,"Verde",IF(S24<=-0.1,"Rojo","Amarillo")),$P24>10000000000,IF(S24>-0.03,"Verde",IF(S24<=-0.07,"Rojo","Amarillo")))} -> Verde | U24: 45707 | V24: 45744 | W24: 45784 | X24: 46335 | Y24: 46335 | Z24: =+IF(AND(O24="En_Ejecución",OR(T24="Rojo",T24="Amarillo")),IF(($Y24-(TODAY())<15),"Rojo",IF(($Y24-TODAY())>=45,"Verde","Amarillo")),O24) -> En_Ejecución | AA24: =+IF(AND(Z24="Amarillo",T24="Rojo"),"En_Seguimiento",IF(AND(Z24="Rojo",T24="Amarillo"),"En_Seguimiento",IF(AND(Z24="Rojo",T24="Rojo"),"En_Seguimiento",IF(AND(Z24="Suspendido",T24="Amarillo"),"En_Seguimiento",IF(AND(Z24="Suspendido",T24="Rojo"),"En_Seguimiento","-"))))) -> - | AB24: No | AC24: - | AD24: 46335 | AE24: LP-026-2024 LOTE 2 | AF24: UT VIAL URBANO BARRANQUILLA | AG24: PEZ VELA INGENIERÍA SAS: 99% (NIT. 901.376.745-0) CFD INGENIERÍA SAS (NIT. 900.556.186- 2) 1% | AH24: CARLOS FRANCISCO DIAZGRANADOS | AI24: CD-12-2025-3646 | AJ24: CONSORCIO DS | AK24: N/A | AL24: N/A | AM24: 52033303778 | AO24: =AM24+AN24 -> 52033303778 | AP24: 0 | AW24: NO APLICA | AX24: Km por Intervenir: 15.94 Km Intervenidos: 0.21 | AY24: Área por Intervenir: 6.99 Área Intervenida: 2.79 | AZ24: - | BA24: - | BB24: - | BC24: No
A25: =+A24+1 -> 24 | B25: Obras Públicas | C25: LP-026-2024 | D25: Línea Económica_Ciudad Dinámica | E25: Trasporte | F25: Barrios a la obra | G25: BAO_IX_VN_M3 | H25: =IFERROR(_xlfn.XLOOKUP(I25,[2]Listas!$C$2:$C$202,[2]Listas!$B$2:$B$202),"-") -> VARIAS | I25: VARIOS | J25: - | K25: =CONCATENATE(CONCATENATE( ABS(TRUNC(L25)),"°", TRUNC((ABS(L25)-ABS(TRUNC(L25)))*60),"'", ROUND((((ABS(L25)-ABS(TRUNC(L25)))*60)-TRUNC((ABS(L25)-ABS(TRUNC(L25)))*60))*60,0),"""", IF(L25<0,"O","E") ),", ",CONCATENATE( ABS(TRUNC(M25)),"°", TRUNC((ABS(M25)-ABS(TRUNC(M25)))*60),"'", ROUND((((ABS(M25)-ABS(TRUNC(M25)))*60)-TRUNC((ABS(M25)-ABS(TRUNC(M25)))*60))*60,0),"""", IF(M25<0,"S","N") )) -> 0°0'0"E, 0°0'0"N | L25: 0 | M25: 0 | N25: Contractual | O25: En_Ejecución | P25: =+AO25+AT25 -> 52104102820 | Q25: 0 | R25: 0.2117 | S25: =+R25-Q25 -> 0.2117 | T25: {=+_xlfn.IFS($P25<=10000000000,IF(S25>-0.05,"Verde",IF(S25<=-0.1,"Rojo","Amarillo")),$P25>10000000000,IF(S25>-0.03,"Verde",IF(S25<=-0.07,"Rojo","Amarillo")))} -> Verde | U25: 45707 | V25: 45744 | W25: 45785 | X25: 46335 | Y25: 46335 | Z25: =+IF(AND(O25="En_Ejecución",OR(T25="Rojo",T25="Amarillo")),IF(($Y25-(TODAY())<15),"Rojo",IF(($Y25-TODAY())>=45,"Verde","Amarillo")),O25) -> En_Ejecución | AA25: =+IF(AND(Z25="Amarillo",T25="Rojo"),"En_Seguimiento",IF(AND(Z25="Rojo",T25="Amarillo"),"En_Seguimiento",IF(AND(Z25="Rojo",T25="Rojo"),"En_Seguimiento",IF(AND(Z25="Suspendido",T25="Amarillo"),"En_Seguimiento",IF(AND(Z25="Suspendido",T25="Rojo"),"En_Seguimiento","-"))))) -> - | AB25: No | AC25: - | AD25: 46335 | AE25: LP-026-2024 LOTE 3 | AF25: UT PAVIMENTOS 2025 | AG25: JS INGENIERIA Y CONSTRUCCIONES SAS: 50% (NIT. 830.504.499-6) J.A. & ASOCIADOS SAS: 50% (NIT. 890.116.998-3) | AH25: JOSE JULIAN SAADE CURE | AI25: CD-12-2025-3646 | AJ25: CONSORCIO DS | AK25: N/A | AL25: N/A | AM25: 52104102820 | AO25: =AM25+AN25 -> 52104102820 | AP25: 5977371358 | AW25: NO APLICA | AX25: Km por Intervenir: 14.97 Km Intervenidos: 0.86 | AY25: Área por Intervenir: 8.97 Área Intervenida: 4.35 | AZ25: - | BA25: - | BB25: - | BC25: No
